<mujoco model="cerbrus_urdf">
  <compiler angle="radian" meshdir="/home/mandred/cerbrus_ws/src/cerbrus_description/meshes/" autolimits="true"/>
  <option cone="elliptic" impratio="100"/>

  <asset>
    <!-- Meshes -->
    <mesh name="base_link" file="base_link.STL" />
    <mesh name="front_left_b_link" file="front_left_b_link.STL" />
    <mesh name="front_left_ul_link" file="front_left_ul_link.STL" />
    <mesh name="front_left_ll_link" file="front_left_ll_link.STL" />
    <mesh name="front_right_b_link" file="front_right_b_link.STL" />
    <mesh name="front_right_ul_link" file="front_right_ul_link.STL" />
    <mesh name="front_right_ll_link" file="front_right_ll_link.STL" />
    <mesh name="back_left_b_link" file="back_left_b_link.STL" />
    <mesh name="back_left_ul_link" file="back_left_ul_link.STL" />
    <mesh name="back_left_ll_link" file="back_left_ll_link.STL" />
    <mesh name="back_right_b_link" file="back_right_b_link.STL" />
    <mesh name="back_right_ul_link" file="back_right_ul_link.STL" />
    <mesh name="back_right_ll_link" file="back_right_ll_link.STL" />
  </asset>

  <worldbody>
    <!-- Base Body -->
    <body name="base_link" pos="0 0 0.5" euler="0 0 0">
    <freejoint/> 
      <inertial pos="0 0 0" mass="1.2203" diaginertia="0.0021324 0.0090463 0.01083"/>
      <geom type="mesh" mesh="base_link" rgba="0.8 0.82 0.93 1" euler="0.035 0 0"/>

      <!-- Front Left Leg -->
      <body name="front_left_b_link" pos="0.24 0.16 -0.06">
        <inertial pos="0.0001 -0.0235 0.029" quat="0.5 0.5 -0.5 0.5" mass="0.025843" diaginertia="1.02e-05 9.01e-06 9.01e-06"/>
        <joint name="front_left_b_joint" pos="0 -0.0228 0.058" axis="1 0 0" range="-1.57 1.57" damping="2"/>
        <geom type="mesh" mesh="front_left_b_link" rgba="0.8 0.82 0.93 1"/>

        <body name="front_left_ul_link" pos="0 -0.005 0">
          <inertial pos="0.0001 -0.0181 -0.065" quat="0.7071 0 0 0.7071" mass="0.1273" diaginertia="2.93e-05 2.73e-05 1.53e-05"/>
          <joint name="front_left_ul_joint" pos="0 -0.02 0" axis="0 1 0" range="-1.57 1.57" damping="2"/>
          <geom type="mesh" mesh="front_left_ul_link" rgba="0.8 0.82 0.93 1"/>

          <body name="front_left_ll_link" pos="0 0.0047 -0.13">
            <inertial pos="0.0023 -0.0231 -0.0886" mass="0.0644" diaginertia="0.000202 0.0002 1.15e-05"/>
            <joint name="front_left_ll_joint" pos="0 -0.02 0" axis="0 1 0" range="-1.57 1.57" damping="2"/>
            <geom type="mesh" mesh="front_left_ll_link" rgba="0.8 0.82 0.93 1" priority="1" solimp="0.015 1 0.0009" condim="6"
            friction="1 0.02 0.01" solref="0.005 1000"/>
          </body>
          
        </body>
      </body>

      <!-- Front Right Leg -->
      <body name="front_right_b_link" pos="0.24 -0.16 -0.06">
        <inertial pos="0.0001 0.0237 0.029" quat="0.5 0.5 -0.5 0.5" mass="0.025843" diaginertia="1.02e-05 9.01e-06 9.01e-06"/>
        <joint name="front_right_b_joint" pos="0 0.0228 0.058" axis="1 0 0" range="-1.57 1.57" damping="2"/>
        <geom type="mesh" mesh="front_right_b_link" rgba="0.8 0.82 0.93 1"/>

        <body name="front_right_ul_link" pos="0 0.005 0">
          <inertial pos="0.0001 0.0191 -0.065" quat="0.7071 0 0 0.7071" mass="0.1273" diaginertia="2.93e-05 2.73e-05 1.53e-05"/>
          <joint name="front_right_ul_joint" pos="0 0.02 0" axis="0 1 0" range="-1.57 1.57" damping="2"/>
          <geom type="mesh" mesh="front_right_ul_link" rgba="0.8 0.82 0.93 1"/>

          <body name="front_right_ll_link" pos="0 -0.0027 -0.13">
            <inertial pos="0.0023 0.0231 -0.0886" mass="0.0644" diaginertia="0.000202 0.0002 1.15e-05"/>
            <joint name="front_right_ll_joint" pos="0 0.02 0" axis="0 1 0" range="-1.57 1.57" damping="2"/>
            <geom type="mesh" mesh="front_right_ll_link" rgba="0.8 0.82 0.93 1" priority="1" solimp="0.015 1 0.0009" condim="6"
            friction="1 0.02 0.01" solref="0.005 1000"/>
          </body>
        </body>
      </body>

      <!-- Back Left Leg -->
      <body name="back_left_b_link" pos="-0.24 0.16 -0.06">
        <inertial pos="0.0001 -0.0235 0.029" quat="0.5 0.5 -0.5 0.5" mass="0.025843" diaginertia="1.02e-05 9.01e-06 9.01e-06"/>
        <joint name="back_left_b_joint" pos="0 -0.0228 0.058" axis="1 0 0" range="-1.57 1.57" damping="2"/>
        <geom type="mesh" mesh="back_left_b_link" rgba="0.8 0.82 0.93 1"/>

        <body name="back_left_ul_link" pos="0 -0.005 0">
          <inertial pos="0.0001 -0.0181 -0.065" quat="0.7071 0 0 0.7071" mass="0.1273" diaginertia="2.93e-05 2.73e-05 1.53e-05"/>
          <joint name="back_left_ul_joint" pos="0 -0.02 0" axis="0 1 0" range="-1.57 1.57" damping="2"/>
          <geom type="mesh" mesh="back_left_ul_link" rgba="0.8 0.82 0.93 1"/>

          <body name="back_left_ll_link" pos="0 0.0047 -0.13">
            <inertial pos="0.0023 -0.0231 -0.0886" mass="0.0644" diaginertia="0.000202 0.0002 1.15e-05"/>
            <joint name="back_left_ll_joint" pos="0 -0.02 0" axis="0 1 0" range="-1.57 1.57" damping="2"/>
            <geom type="mesh" mesh="back_left_ll_link" rgba="0.8 0.82 0.93 1" priority="1" solimp="0.015 1 0.0009" condim="6"
            friction="1 0.02 0.01" solref="0.005 1000"/>
          </body>
        </body>
      </body>

      <!-- Back Right Leg -->
      <body name="back_right_b_link" pos="-0.24 -0.16 -0.06">
        <inertial pos="0.0001 0.0235 0.029" quat="0.5 0.5 -0.5 0.5" mass="0.025843" diaginertia="1.02e-05 9.01e-06 9.01e-06"/>
        <joint name="back_right_b_joint" pos="0 0.0228 0.058" axis="1 0 0" range="-1.57 1.57" damping="2"/>
        <geom type="mesh" mesh="back_right_b_link" rgba="0.8 0.82 0.93 1"/>

        <body name="back_right_ul_link" pos="0 0.005 0">
          <inertial pos="0.0001 0.0181 -0.065" quat="0.7071 0 0 0.7071" mass="0.1273" diaginertia="2.93e-05 2.73e-05 1.53e-05"/>
          <joint name="back_right_ul_joint" pos="0 0.02 0" axis="0 1 0" range="-1.57 1.57" damping="2"/>
          <geom type="mesh" mesh="back_right_ul_link" rgba="0.8 0.82 0.93 1"/>

          <body name="back_right_ll_link" pos="0 -0.0047 -0.13">
            <inertial pos="0.0023 0.0231 -0.0886" mass="0.0644" diaginertia="0.000202 0.0002 1.15e-05"/>
            <joint name="back_right_ll_joint" pos="0 0.02 0" axis="0 1 0" range="-1.57 1.57" damping="2"/>
            <geom type="mesh" mesh="back_right_ll_link" rgba="0.8 0.82 0.93 1" priority="1" solimp="0.015 1 0.0009" condim="6"
            friction="1 0.02 0.01" solref="0.005 1000"/>
          </body>
        </body>
      </body>
    </body>
  </worldbody>

  <actuator>
    <!-- Front Left -->
    <position name="FL_hip" joint="front_left_b_joint" kp="20" ctrlrange="0 1.57"/>
    <position name="FL_thigh" joint="front_left_ul_joint" kp="20" ctrlrange="-1.57 1.57"/>
    <position name="FL_calf" joint="front_left_ll_joint" kp="20" ctrlrange="-1.57 1.57"/>

    <!-- Front Right -->
    <position name="FR_hip" joint="front_right_b_joint" kp="20" ctrlrange="-1.57 0"/>
    <position name="FR_thigh" joint="front_right_ul_joint" kp="20" ctrlrange="-1.57 1.57"/>
    <position name="FR_calf" joint="front_right_ll_joint" kp="20" ctrlrange="-1.57 1.57"/>

    <!-- Back Left -->
    <position name="RL_hip" joint="back_left_b_joint" kp="20" ctrlrange="0 1.57"/>
    <position name="RL_thigh" joint="back_left_ul_joint" kp="20" ctrlrange="-1.57 1.57"/>
    <position name="RL_calf" joint="back_left_ll_joint" kp="20" ctrlrange="-1.57 1.57"/>

    <!-- Back Right -->
    <position name="RR_hip" joint="back_right_b_joint" kp="20" ctrlrange="-1.57 0"/>
    <position name="RR_thigh" joint="back_right_ul_joint" kp="20" ctrlrange="-1.57 1.57"/>
    <position name="RR_calf" joint="back_right_ll_joint" kp="20" ctrlrange="-1.57 1.57"/>
  </actuator>
</mujoco>
